<?xml version="1.0"?>
<robot name="Buddy_UDRF" xmlns:xacro="http://www.ros.org/wiki/xacro">

  <link name="base_link">
    <collision>
      <origin xyz="0 0 0" rpy="0 0 0" />
    </collision>
  </link>

  <link name="Servo_v2_1">
    <collision>
      <origin xyz="-0.018 -0.0 -0.026169" rpy="0 0 0" />
    </collision>
  </link>

  <link name="Servo_Horn_v7_1">
    <collision>
      <origin xyz="-0.0011 -0.0 -0.040369" rpy="0 0 0" />
    </collision>
  </link>

  <link name="buddy_jr_basic_base_pivot_v9_1">
    <collision>
      <origin xyz="-0.0011 -0.0 -0.040369" rpy="0 0 0" />
    </collision>
  </link>

  <link name="Servo_Horn_v7__1__1">
    <collision>
      <origin xyz="-0.0001 -0.0 -0.062369" rpy="0 0 0" />
    </collision>
  </link>

  <link name="Servo_v2__1__1">
    <collision>
      <origin xyz="-0.0001 -0.0 -0.062369" rpy="0 0 0" />
    </collision>
  </link>

  <link name="buddy_jr_basic_arm_v6_1">
    <collision>
      <origin xyz="-0.0143 -0.0 -0.056269" rpy="0 0 0" />
    </collision>
  </link>

  <link name="Servo_Horn_v7__2__1">
    <collision>
      <origin xyz="-0.0163 -1e-06 -0.142469" rpy="0 0 0" />
    </collision>
  </link>

  <link name="Servo_v2__2__1">
    <collision>
      <origin xyz="-0.0163 -1e-06 -0.142469" rpy="0 0 0" />
    </collision>
  </link>

  <link name="buddy_jr_basic_arm_v6__1__1">
    <collision>
      <origin xyz="-0.0021 -1e-06 -0.159369" rpy="0 0 0" />
    </collision>
  </link>

  <link name="Servo_Horn_v7__3__1">
    <collision>
      <origin xyz="-0.0001 -2e-06 -0.221569" rpy="0 0 0" />
    </collision>
  </link>

  <link name="Servo_v2__3__1">
    <collision>
      <origin xyz="-0.0001 -2e-06 -0.221569" rpy="0 0 0" />
    </collision>
  </link>

  <link name="buddy_jr_basic_camera_holder_v6_1">
    <collision>
      <origin xyz="-0.0143 -2e-06 -0.238469" rpy="0 0 0" />
    </collision>
  </link>

  <joint name="Rigid 1" type="fixed">
    <origin xyz="0.018 0.0 0.026169" rpy="0 0 0" />
    <parent link="base_link" />
    <child link="Servo_v2_1" />
  </joint>

  <joint name="Revolute 13" type="continuous">
    <origin xyz="-0.0169 0.0 0.0142" rpy="0 0 0" />
    <parent link="Servo_v2_1" />
    <child link="Servo_Horn_v7_1" />
    <axis xyz="0.0 8e-06 1.0" />
  </joint>

  <joint name="Rigid 14" type="fixed">
    <origin xyz="0.0 0.0 0.0" rpy="0 0 0" />
    <parent link="Servo_Horn_v7_1" />
    <child link="buddy_jr_basic_base_pivot_v9_1" />
  </joint>

  <joint name="Rigid 15" type="fixed">
    <origin xyz="-0.001 0.0 0.022" rpy="0 0 0" />
    <parent link="buddy_jr_basic_base_pivot_v9_1" />
    <child link="Servo_Horn_v7__1__1" />
  </joint>

  <joint name="Revolute 16" type="continuous">
    <origin xyz="0.0 0.0 0.0" rpy="0 0 0" />
    <parent link="Servo_Horn_v7__1__1" />
    <child link="Servo_v2__1__1" />
    <axis xyz="-1.0 0.0 0.0" />
  </joint>

  <joint name="Rigid 17" type="fixed">
    <origin xyz="0.0142 0.0 -0.0061" rpy="0 0 0" />
    <parent link="Servo_v2__1__1" />
    <child link="buddy_jr_basic_arm_v6_1" />
  </joint>

  <joint name="Rigid 18" type="fixed">
    <origin xyz="0.002 1e-06 0.0862" rpy="0 0 0" />
    <parent link="buddy_jr_basic_arm_v6_1" />
    <child link="Servo_Horn_v7__2__1" />
  </joint>

  <joint name="Rigid 19" type="fixed">
    <origin xyz="0.0 0.0 0.0" rpy="0 0 0" />
    <parent link="Servo_Horn_v7__2__1" />
    <child link="Servo_v2__2__1" />
  </joint>

  <joint name="Rigid 20" type="fixed">
    <origin xyz="-0.0142 0.0 0.0169" rpy="0 0 0" />
    <parent link="Servo_v2__2__1" />
    <child link="buddy_jr_basic_arm_v6__1__1" />
  </joint>

  <joint name="Rigid 21" type="fixed">
    <origin xyz="-0.002 1e-06 0.0622" rpy="0 0 0" />
    <parent link="buddy_jr_basic_arm_v6__1__1" />
    <child link="Servo_Horn_v7__3__1" />
  </joint>

  <joint name="Revolute 22" type="continuous">
    <origin xyz="0.0 0.0 0.0" rpy="0 0 0" />
    <parent link="Servo_Horn_v7__3__1" />
    <child link="Servo_v2__3__1" />
    <axis xyz="-1.0 0.0 -0.0" />
  </joint>

  <joint name="Rigid 23" type="fixed">
    <origin xyz="0.0142 0.0 0.0169" rpy="0 0 0" />
    <parent link="Servo_v2__3__1" />
    <child link="buddy_jr_basic_camera_holder_v6_1" />
  </joint>

</robot>
